<?xml version="1.0" encoding="utf-8"?>
<!-- =================================================================================== -->
<!-- |    This document was autogenerated by xacro from 6dof_macro.urdf.xacro          | -->
<!-- |    EDITING THIS FILE BY HAND IS NOT RECOMMENDED                                 | -->
<!-- =================================================================================== -->
<robot name="multiple">
  <material name="blue">
    <color rgba="0 0 0.8 1"/>
  </material>
  <material name="white">
    <color rgba="1 1 1 1"/>
  </material>
  <material name="red">
    <color rgba="0.8 0 0 1"/>
  </material>
  <link name="world"/>
  <joint name="fixed" type="fixed">
    <parent link="world"/>
    <child link="base"/>
    <origin xyz="0 0 2"/>
  </joint>
  <link name="ee">
    <visual>
      <geometry>
        <box size="0.19 0.19 0.5"/>
      </geometry>
      <origin rpy="0 0 0" xyz="0 0 0.25"/>
      <material name="red"/>
    </visual>
  </link>
  <link name="base">
    <visual>
      <geometry>
        <box size="0.205 0.205 0.1"/>
      </geometry>
      <origin rpy="0 0 0" xyz="0 0 0.05"/>
      <material name="blue"/>
    </visual>
  </link>
  <joint name="baseu1" type="revolute">
    <parent link="base"/>
    <child link="u1"/>
    <axis xyz="0 1 0"/>
    <origin xyz="0 0 0.1"/>
    <limit effort="1" lower="-3.14" upper="3.14" velocity="1"/>
  </joint>
  <link name="u1">
    <visual>
      <geometry>
        <box size="0.204 0.204 0.1"/>
      </geometry>
      <origin rpy="0 0 0" xyz="0 0 0.05"/>
      <material name="white"/>
    </visual>
  </link>
  <joint name="u1u2" type="revolute">
    <parent link="u1"/>
    <child link="u2"/>
    <axis xyz="1 0 0"/>
    <origin xyz="0 0 0.1"/>
    <limit effort="1" lower="-3.14" upper="3.14" velocity="1"/>
  </joint>
  <link name="u2">
    <visual>
      <geometry>
        <box size="0.203 0.203 2"/>
      </geometry>
      <origin rpy="0 0 0" xyz="0 0 1.0"/>
      <material name="blue"/>
    </visual>
  </link>
  <joint name="u2u3" type="revolute">
    <parent link="u2"/>
    <child link="u3"/>
    <axis xyz="-1 0 0"/>
    <origin xyz="0 0 2"/>
    <limit effort="1" lower="-3.14" upper="3.14" velocity="1"/>
  </joint>
  <link name="u3">
    <visual>
      <geometry>
        <box size="0.202 0.202 2"/>
      </geometry>
      <origin rpy="0 0 0" xyz="0 0 1.0"/>
      <material name="white"/>
    </visual>
  </link>
  <joint name="u3u4" type="revolute">
    <parent link="u3"/>
    <child link="u4"/>
    <axis xyz="0 0 1"/>
    <origin xyz="0 0 2"/>
    <limit effort="1" lower="-3.14" upper="3.14" velocity="1"/>
  </joint>
  <link name="u4">
    <visual>
      <geometry>
        <box size="0.201 0.201 0.1"/>
      </geometry>
      <origin rpy="0 0 0" xyz="0 0 0.05"/>
      <material name="blue"/>
    </visual>
  </link>
  <joint name="u4u5" type="revolute">
    <parent link="u4"/>
    <child link="u5"/>
    <axis xyz="1 0 0"/>
    <origin xyz="0 0 0.1"/>
    <limit effort="1" lower="-3.14" upper="3.14" velocity="1"/>
  </joint>
  <link name="u5">
    <visual>
      <geometry>
        <box size="0.2 0.2 0.1"/>
      </geometry>
      <origin rpy="0 0 0" xyz="0 0 0.05"/>
      <material name="white"/>
    </visual>
  </link>
  <joint name="u5ee" type="revolute">
    <parent link="u5"/>
    <child link="ee"/>
    <axis xyz="0 1 0"/>
    <origin xyz="0 0 0.1"/>
    <limit effort="1" lower="-3.14" upper="3.14" velocity="1"/>
  </joint>
</robot>

