<?xml version="1.0"?>

<xacro:property name="width" value="0.2" />
<xacro:property name="bodylen" value="0.6" />

<robot name="multiple">

  <material name="blue">
    <color rgba="0 0 0.8 1"/>
  </material>

  <material name="white">
    <color rgba="1 1 1 1"/>
  </material>

  <link name="u0">
    <visual>
      <geometry>
        <cylinder length="0.1" radius="0.1"/>
      </geometry>
      <origin rpy="0.0 0.0 0.0" xyz="0.0 0.0 -0.05"/>
      <material name="blue"/>
    </visual>
  </link>

  <link name="u1">
    <visual>
      <geometry>
        <cylinder length="0.5" radius="0.05"/>
      </geometry>
      <origin rpy="0.0 0.0 0.0" xyz="0.0 0.0 0.25"/>
      <material name="white"/>
    </visual>
  </link>

  <link name="u2">
    <visual>
      <geometry>
        <cylinder length="0.5" radius="0.03"/>
      </geometry>
      <origin rpy="0.0 0.0 0.0" xyz="0.0 0.0 0.25"/>
      <material name="blue"/>
    </visual>
  </link>

  <link name="u3">
    <visual>
      <geometry>
        <cylinder length="0.1" radius="0.03"/>
      </geometry>
      <origin rpy="-1.57 0.0 0.0" xyz="0.0 0.05 0.0"/>
      <material name="white"/>
    </visual>
  </link>

  <link name="u4">
    <visual>
      <geometry>
        <cylinder length="0.1" radius="0.03"/>
      </geometry>
      <origin rpy="0.0 0.0 0.0" xyz="0.0 0.0 0.05"/>
      <material name="blue"/>
    </visual>
  </link>

  <link name="u5">
    <visual>
      <geometry>
        <cylinder length="0.1" radius="0.03"/>
      </geometry>
      <origin rpy="-1.57 0.0 0.0" xyz="0.0 0.05 0.0"/>
      <material name="white"/>
    </visual>
  </link>

  <link name="u6">
    <visual>
      <geometry>
        <cylinder length="0.01" radius="0.06"/>
      </geometry>
      <origin rpy="0.0 -1.57 0.0" xyz="0.0 0.0 0.0"/>
      <material name="white"/>
    </visual>
  </link>

  <link name="world"/>

  <!-- <joint name="fixed" type="fixed">
    <parent link="world"/>
    <child link="u0"/>
  </joint> -->

  <joint name="base" type="revolute">
    <parent link="world"/>
    <child link="u0"/>
    <origin rpy="0.0 0.0 0.0" xyz="0.0 0.0 0.1"/>
    <axis xyz="0.0 0.0 1.0"/>
    <limit effort="10.0" lower="-3.14" upper="3.14" velocity="1.0"/>
  </joint>

  <joint name="u01" type="revolute">
    <parent link="u0"/>
    <child link="u1"/>
    <origin rpy="0.0 0.0 0.0" xyz="0.0 0.1 0.0"/>
    <axis xyz="0.0 1.0 0.0"/>
    <limit effort="10.0" lower="-3.14" upper="3.14" velocity="1.0"/>
  </joint>

  <joint name="u12" type="revolute">
    <parent link="u1"/>
    <child link="u2"/>
    <origin rpy="0.0 0.0 0.0" xyz="0.0 -0.1 0.5"/>
    <axis xyz="0.0 -1.0 0.0"/>
    <limit effort="10.0" lower="-3.14" upper="3.14" velocity="1.0"/>
  </joint>

  <joint name="u23" type="revolute">
    <parent link="u2"/>
    <child link="u3"/>
    <origin rpy="0.0 0.0 0.0" xyz="0.0 0.0 0.5"/>
    <axis xyz="0.0 1.0 0.0"/>
    <limit effort="10.0" lower="-3.14" upper="3.14" velocity="1.0"/>
  </joint>

  <joint name="u34" type="revolute">
    <parent link="u3"/>
    <child link="u4"/>
    <origin rpy="0.0 0.0 0.0" xyz="0.0 0.1 0.0"/>
    <axis xyz="0.0 0.0 1.0"/>
    <limit effort="10.0" lower="-3.14" upper="3.14" velocity="1.0"/>
  </joint>

  <joint name="u45" type="revolute">
    <parent link="u4"/>
    <child link="u5"/>
    <origin rpy="0.0 0.0 0.0" xyz="0.0 0.0 0.1"/>
    <axis xyz="0.0 1.0 0.0"/>
    <limit effort="10.0" lower="-3.14" upper="3.14" velocity="1.0"/>
  </joint>

  <joint name="u56" type="fixed">
    <parent link="u5"/>
    <child link="u6"/>
    <origin rpy="0.0 0.0 1.57" xyz="0.0 0.1 0.0"/>
  </joint>

</robot>